<?xml version="1.0"?>
<robot name="apostile_robot">
    <link name="base_link">

        <visual>
            
        
            <geometry>
                <box size="0.366 0.2934 0.136"/>
            </geometry>
            <material name = "white">

                <color rgba="255 255 255 1"/>
            </material>
        </visual>
        
        
    </link>

    <link name="front_left_wheel">
        <visual>
            <geometry>
                <cylinder radius="0.06" length="0.025"/>
            </geometry>
            <material name="red">
                <color rgba="1 0.0 0.0 1"/>
            </material>
        </visual>
       
        
    </link>
    <joint name="front_left_wheel_joint" type="continuous">
        <parent link="base_link"/>
        <child link="front_left_wheel"/>
        <axis xyz="0 0 1"/>
        <origin xyz="0.10509 0.11577 -0.03856" rpy="-1.5707 0 0"/>
    </joint>

    <link name="front_right_wheel">
        <visual>
            <geometry>
                <cylinder radius="0.06" length="0.025"/>
            </geometry>

            <material name="red">
                <color rgba="1 0.0 0.0 1"/>
            </material>

            
        </visual>

        
    </link>


    <joint name="front_right_wheel_joint" type="continuous">
        <parent link="base_link"/>
        <child link="front_right_wheel"/>
        <axis xyz="0 0 1"/>
        <origin xyz="0.10509 -0.11577 -0.03856" rpy="-1.5707 0 0"/>
    </joint>


    <link name="back_left_wheel">
        <visual>
            <geometry>
                <cylinder radius="0.06" length="0.025"/>
            </geometry>
            <material name="red">
                <color rgba="1 0.0 0.0 1"/>
            </material>
        </visual>
        
        
    </link>

    <joint name="back_left_wheel_joint" type="continuous">
        <parent link="base_link"/>
        <child link="back_left_wheel"/>
        <axis xyz="0 0 1"/>
        <origin xyz="-0.10509 0.11577 -0.03856" rpy="-1.5707 0 0"/>
    </joint>


    
    <link name="back_right_wheel">
        <visual>
            <geometry>
                <cylinder radius="0.06" length="0.025"/>
            </geometry>

            <material name="red">
                <color rgba="1 0.0 0.0 1"/>
            </material>
        </visual>
        
    </link>


    <joint name="back_right_wheel_joint" type="continuous">
        <parent link="base_link"/>
        <child link="back_right_wheel"/>
        <axis xyz="0 0 1"/>
        <origin xyz="-0.10509 -0.11577 -0.03856" rpy="-1.5707 0 0"/>
    </joint>

    <link name="lidar">
        <visual>
            <geometry>
                <cylinder radius="0.035" length="0.055"/>
            </geometry>
        
            <material name="blue">
                <color rgba="0.0 0.0 1 1"/>
            </material>
        <visual>
            
    </link>

    <joint name="lidar_joint" type="fixed">
        <parent link="base_link"/>
        <child link="lidar"/>
        <origin xyz="0.0 0.0 0.0955" rpy="0.0 0.0 0.0"/>
    </joint>

    

    
    
    
</robot>
