<?xml version="1.0"?>
<robot name="apostile_robot">

    
    

    
    


    <!--base_link-->
    <link name="Robot_base">

        <visual>
            
        
            <geometry>
                <box size="0.366 0.2934 0.136"/>
            </geometry>
            <material name = "white">

                <color rgba="10 10 10 0.1"/>
            </material>
        </visual>
        <collision>
            <geometry>
                <box size="0.366 0.2934 0.136"/>
            </geometry>
            
        </collision>

        <inertial>
            <mass value="5.6"/>
            <inertia ixx="0.0711" ixy="0.0" ixz="0.0" iyy="0.1025" iyz="0.0" izz="0.0486"/>
        </inertial>
        
    </link>


    <!-- <link name="imu_data"> 

        <visual>
            
        
            <geometry>
                <box size="0.001 0.001 0.001"/>
            </geometry>
            <material name = "white">

                <color rgba="10 10 10 0.1"/>
            </material>
        </visual>
        <collision>
            <geometry>
                <box size="0.366 0.2934 0.136"/>
            </geometry>
            
        </collision>

    </link>

    <joint name="imu_joint" type="fixed">
    <parent link="Robot_base"/>
    <child link="imu_data"/>
    <axis xyz="0 0 0"/>
    <origin xyz="0.00 0.00 0.00" rpy="0 0 0"/>
    
    </joint>-->

    

    
    




    <!--front_left_wheel-->
    
    <link name="front_left_wheel">
        <visual>
            <geometry>
                <cylinder radius="0.06" length="0.025"/>
            </geometry>
            <material name="red">
                <color rgba="1 0.0 0.0 1"/>
            </material>
        </visual>

        <collision>
            <geometry>
                <cylinder radius="0.06" length="0.025"/>
            </geometry>
        </collision>
        <inertial>
            <mass value="0.6"/>
            <inertia ixx="5.7125e-4" ixy="0.0" ixz="0.0" iyy="5.7125e-4" iyz="0.0" izz="1.08e-3"/>
        </inertial>
       
    </link>
    <joint name="front_left_wheel_joint" type="continuous">
        <parent link="Robot_base"/>
        <child link="front_left_wheel"/>
        <axis xyz="0 0 1"/>
        <origin xyz="0.10509 0.11577 -0.03856" rpy="-1.5707 0 0"/>
    </joint>









    <!--front_right_wheel-->
    
    <link name="front_right_wheel">
        <visual>
            <geometry>
                <cylinder radius="0.06" length="0.025"/>
            </geometry>

            <material name="red">
                <color rgba="1 0.0 0.0 1"/>
            </material>

            
        </visual>
        <collision>
            <geometry>
                <cylinder radius="0.06" length="0.025"/>
            </geometry>
        </collision>
        <inertial>
            <mass value="0.6"/>
            <inertia ixx="5.7125e-4" ixy="0.0" ixz="0.0" iyy="5.7125e-4" iyz="0.0" izz="1.08e-3"/>
        </inertial>

    </link>
    <joint name="front_right_wheel_joint" type="continuous">
        <parent link="Robot_base"/>
        <child link="front_right_wheel"/>
        <axis xyz="0 0 1"/>
        <origin xyz="0.10509 -0.11577 -0.03856" rpy="-1.5707 0 0"/>
    </joint>


    



    


    <!--back_left_wheel-->
    
    <link name="back_left_wheel">
        <visual>
            <geometry>
                <cylinder radius="0.06" length="0.025"/>
            </geometry>
            <material name="red">
                <color rgba="1 0.0 0.0 1"/>
            </material>
        </visual>
        <collision>
            <geometry>
                <cylinder radius="0.06" length="0.025"/>
            </geometry>
        </collision>
        <inertial>
            <mass value="0.6"/>
            <inertia ixx="5.7125e-4" ixy="0.0" ixz="0.0" iyy="5.7125e-4" iyz="0.0" izz="1.08e-3"/>
        </inertial>

    </link>

    <joint name="back_left_wheel_joint" type="continuous">
        <parent link="Robot_base"/>
        <child link="back_left_wheel"/>
        <axis xyz="0 0 1"/>
        <origin xyz="-0.10509 0.11577 -0.03856" rpy="-1.5707 0 0"/>
    </joint>


    
    
    
    



    <!--back_right_wheel-->
    
    <link name="back_right_wheel">
        <visual>
            <geometry>
                <cylinder radius="0.06" length="0.025"/>
            </geometry>

            <material name="red">
                <color rgba="1 0.0 0.0 1"/>
            </material>
        </visual>
        <collision>
            <geometry>
                <cylinder radius="0.06" length="0.025"/>
            </geometry>
        </collision>
        <inertial>
            <mass value="0.6"/>
            <inertia ixx="5.7125e-4" ixy="0.0" ixz="0.0" iyy="5.7125e-4" iyz="0.0" izz="1.08e-3"/>
        </inertial>
        
    </link>


    <joint name="back_right_wheel_joint" type="continuous">
        <parent link="Robot_base"/>
        <child link="back_right_wheel"/>
        <axis xyz="0 0 1"/>
        <origin xyz="-0.10509 -0.11577 -0.03856" rpy="-1.5707 0 0"/>
    </joint>









    <!--lidar-->

    <link name="lidar">
        <visual>
            <geometry>
                <cylinder radius="0.035" length="0.055"/>
            </geometry>

            <material name="blue">
                <color rgba="0.0 0.0 1 1.0"/>
            </material>
        </visual>
        <collision>
            <geometry>
                <cylinder radius="0.035" length="0.055"/>
            </geometry>
        </collision>
        
            
    </link>

    <joint name="lidar_joint" type="fixed">
        <parent link="Robot_base"/>
        <child link="lidar"/>
        <origin xyz="0.0 0.0 0.095" rpy="0.0 0.0 0.0"/>
    </joint>







    <!-- apostile_robot_ gazebo_plugins-->
    <gazebo reference="lidar">
        <sensor type="ray" name="head_hokuyo_sensor">
            <pose>0 0 0 0 0 0</pose>
            <visualize>true</visualize>
            <update_rate>40</update_rate>
            <ray>
                <scan>
                    <horizontal>
                        <samples>720</samples>
                        <resolution>1</resolution>
                        <min_angle>-1.570796</min_angle>
                        <max_angle>1.570796</max_angle>
                    </horizontal>
                </scan>
                <range>
                    <min>0.08</min>
                    <max>12.0</max>
                    <resolution>0.01</resolution>
                </range>
                <noise>
                    <type>gaussian</type>
          <!-- Noise parameters based on published spec for Hokuyo laser
               achieving "+-30mm" accuracy at range < 10m.  A mean of 0.0m and
               stddev of 0.01m will put 99.7% of samples within 0.03m of the true
               reading. -->
                    <mean>0.0</mean>
                    <stddev>0.01</stddev>
                </noise>
            </ray>
            <plugin name="gazebo_ros_head_hokuyo_controller" filename="libgazebo_ros_laser.so">
                <topicName>/scan</topicName>
                <frameName>lidar</frameName> 
                <!-- frame name should match link name  -->
            </plugin>
        </sensor>
    </gazebo>





    <!--back wheel-->

    <gazebo>
        <plugin name="differential_drive_controllerr" filename="libgazebo_ros_diff_drive.so">

            <!-- Plugin update rate in Hz -->
            <updateRate>100</updateRate>

            <!-- Name of left joint, defaults to `left_joint` -->
            <leftJoint>back_left_wheel_joint</leftJoint>

            <!-- Name of right joint, defaults to `right_joint` -->
            <rightJoint>back_right_wheel_joint</rightJoint>

            <!-- The distance from the center of one wheel to the other, in meters, defaults to 0.34 m -->
            <wheelSeparation>0.23154</wheelSeparation>

            <!-- Diameter of the wheels, in meters, defaults to 0.15 m -->
            <wheelDiameter>0.12</wheelDiameter>

            <!-- Wheel acceleration, in rad/s^2, defaults to 0.0 rad/s^2 -->
            <wheelAcceleration>5</wheelAcceleration>

            <!-- Maximum torque which the wheels can produce, in Nm, defaults to 5 Nm -->
            <wheelTorque>40</wheelTorque>

            <!-- Topic to receive geometry_msgs/Twist message commands, defaults to `cmd_vel` -->
            <commandTopic>cmd_vel</commandTopic>

            <!-- Topic to publish nav_msgs/Odometry messages, defaults to `odom` -->
            <odometryTopic>odom</odometryTopic>

            <!-- Odometry frame, defaults to `odom` -->
            <odometryFrame>odom</odometryFrame>

            <!-- Robot frame to calculate odometry from, defaults to `base_footprint` -->
            <robotBaseFrame>Robot_base</robotBaseFrame> <!--name should be changed according to our base link name-->

            <!-- Odometry source, 0 for ENCODER, 1 for WORLD, defaults to WORLD -->
            <odometrySource>1</odometrySource>

            <!-- Set to true to publish transforms for the wheel links, defaults to false -->
            <publishWheelTF>true</publishWheelTF>

            <!-- Set to true to publish transforms for the odometry, defaults to true -->
            <publishOdom>true</publishOdom>

            <!-- Set to true to publish sensor_msgs/JointState on /joint_states for the wheel joints, defaults to false -->
            <publishWheelJointState>true</publishWheelJointState>


            <!-- Set to true to swap right and left wheels, defaults to true -->
            <legacyMode>false</legacyMode>

            <publishTf>true</publishTf>
        </plugin>
    </gazebo>

     



        <!--front wheels-->


    <gazebo>
        <plugin name="differential_drive_controller" filename="libgazebo_ros_diff_drive.so">

            <!-- Plugin update rate in Hz -->
            <updateRate>100</updateRate>

            <!-- Name of left joint, defaults to `left_joint` -->
            <leftJoint>front_left_wheel_joint</leftJoint>

            <!-- Name of right joint, defaults to `right_joint` -->
            <rightJoint>front_right_wheel_joint</rightJoint>

            <!-- The distance from the center of one wheel to the other, in meters, defaults to 0.34 m -->
            <wheelSeparation>0.23154</wheelSeparation>

            <!-- Diameter of the wheels, in meters, defaults to 0.15 m -->
            <wheelDiameter>0.12</wheelDiameter>

            <!-- Wheel acceleration, in rad/s^2, defaults to 0.0 rad/s^2 -->
            <wheelAcceleration>5</wheelAcceleration>

            <!-- Maximum torque which the wheels can produce, in Nm, defaults to 5 Nm -->
            <wheelTorque>40</wheelTorque>

            <!-- Topic to receive geometry_msgs/Twist message commands, defaults to `cmd_vel` -->
            <commandTopic>cmd_vel</commandTopic>

            <!-- Topic to publish nav_msgs/Odometry messages, defaults to `odom` -->
            <odometryTopic>odom</odometryTopic>

            <!-- Odometry frame, defaults to `odom` -->
            <odometryFrame>odom</odometryFrame>

            <!-- Robot frame to calculate odometry from, defaults to `base_footprint` -->
            <robotBaseFrame>Robot_base</robotBaseFrame> <!--name should be changed according to our base link name-->

            <!-- Odometry source, 0 for ENCODER, 1 for WORLD, defaults to WORLD -->
            <odometrySource>1</odometrySource>

            <!-- Set to true to publish transforms for the wheel links, defaults to false -->
            <publishWheelTF>true</publishWheelTF>

            <!-- Set to true to publish transforms for the odometry, defaults to true -->
            <publishOdom>true</publishOdom>

            <!-- Set to true to publish sensor_msgs/JointState on /joint_states for the wheel joints, defaults to false -->
            <publishWheelJointState>true</publishWheelJointState>

            <!-- Set to true to swap right and left wheels, defaults to true -->
            <legacyMode>false</legacyMode>

            <publishTf>true</publishTf>
        </plugin>
    </gazebo>

    
    <gazebo reference="imu_link">
        <gravity>true</gravity>
        <sensor name="imu_sensor" type="imu">
            <always_on>true</always_on>
            <update_rate>100</update_rate>
            <visualize>true</visualize>
             <topic>imu_data</topic>
            <plugin filename="libgazebo_ros_imu_sensor.so" name="imu_plugin">
                <topicName>imu</topicName>
                <bodyName>imu_link</bodyName>
                <updateRateHZ>10.0</updateRateHZ>
                <gaussianNoise>0.0</gaussianNoise>
                <xyzOffset>0 0 0</xyzOffset>
                <rpyOffset>0 0 0</rpyOffset>
                <frameName>imu_link</frameName>
                <initialOrientationAsReference>false</initialOrientationAsReference>
            </plugin>
            <pose>0 0 0 0 0 0</pose>
        </sensor>
    </gazebo>
    

    
            
        


</robot>
